# 예외 처리 

## 구문 오류 vs 예외 
구문오류
- 프로그래밍 언어의 문법 규칙 위반 시 발생 Parsing Error 라고도 함 
- 코드가 실행되기 전인 컴파일 타임에 발생

예외 
- Exception 혹은 Runtime Error 
- 프로그래밍 실행 중 발생 

## 예외 처리 
기본 예외 처리: 대체적으로 조건문을 사용하여 처리 
오류가 발생할 가능성이 있는 코드를 실행 전 검사하여 방지

고급 예외 처리: try catch finally 구문 활용
catch와 finally 둘중 하나 생략 가능
finally  구문은 무조건 수행해야 하는 작업 
코드 실행 중에 오류가 발생할 때 처리하는 법 

![[08. 예외 처리-20240529191648932.webp|544]]

> try - catch 블록안의 변수는 함수나 for문 같이 지역 변수로 취급된다. 그냥 중괄호를 쓰는 문법 안의 변수는 대부분 지역 변수로 취급된다고 이해하면 된다.
 [catch_-_finally__문](https://inpa.tistory.com/entry/JS-%F0%9F%93%9A-%EC%98%88%EC%99%B8-%EC%B2%98%EB%A6%AC#try_-_catch_-_finally__%EB%AC%B8)

```js
try {
    // 오류를 발생시키는 코드
    throw new Error("An example error");
} catch (error) {
    // catch 블록 내에서 예외 식별자 접근 가능
    console.log("Error caught:", error.message); // 출력: Error caught: An example error
}

// catch 블록이 끝난 후 예외 식별자에 접근 시도
try {
    console.log(error.message); // ReferenceError: error is not defined
} catch (e) {
    console.log("Outside catch block:", e.message);
}
```
❓finally 구문은 언제 필요할까 
try catch 절이 끝나더라도 반드시 실행되어야 할 코드가 있다면 finally 구문으로 지정해야함 
return을 사용해 명시적으로 스크립트를 종료하려하더라도 finally  구문은 실행되게 되어있음 

ex. MDN 예시
```js
function f() {
  try {
    console.log(0);
    throw "bogus";
  } catch (e) {
    console.log(1);
    return true; // finally 블록의 실행이 끝날 때까지 중단됨
    console.log(2); // 접근 불가
  } finally {
    console.log(3);
    return false; // 앞선 return보다 우선함
    console.log(4); // 접근 불가
  }
  // return false가 실행됨
  console.log(5); // 접근 불가
}
console.log(f()); // 0, 1, 3, false

```
## 
예외 객체
예외 객체는 catch 블록의 매개변수로만 전달되어야 함 

예외 식별자는 catch 블록에 진입해야 생성됨, 밖으로 나가면(=catch 블록의 실행이 끝나면) 예외 식별자 접근 불가 
ex.

## 예외 발생 
예외를 강제로 발생시켜야 하는 상황 
- 사용자에게 주의를 주어 의도한 대로 처리하도록 유도
+
- 에러의 종류를 구분해야 할때 
- 에러 객체에 기능을 추가해야 할 때 

throw 문을 활용 
>**참고:** `catch` 블록 안에서 오류를 기록할 땐 `console.log()`보다 `console.error()`를 사용하는 것을 추천합니다. `console.error()`는 출력 형식도 오류에 적합하고, 현재 페이지에서 발생한 오류의 목록도 업데이트합니다.
>출처: MDN